Workbook

Sheet Annual Extremes 1965-2025
A1: Fraser River at Mission (WSC 08MH024) — annual maximum and minimum water level and discharge
A2: Source: Water Survey of Canada / ECCC Water Office (HYDAT), Annual Extremes & Peak reports, retrieved 2026-10-05. Levels published in station ASSUMED datum.
A3: Assumed datum → Geodetic Survey of Canada (GSC) datum, add (m): | H3: 0.043
A5: Year | B5: Max daily level date | C5: Max daily level (m, assumed) | D5: Max daily level (m GSC) | E5: Max instantaneous level date/time (PST) | F5: Max instantaneous level (m, assumed) | G5: Min daily level date | H5: Min daily level (m, assumed) | I5: Max daily discharge date | J5: Max daily discharge (m³/s) | K5: Max instantaneous discharge date/time (PST) | L5: Max instantaneous discharge (m³/s) | M5: Min daily discharge date | N5: Min daily discharge (m³/s) | O5: Flags
A6: 1965 | I6: 1965-06-07 | J6: 9400
A7: 1966 | I7: 1966-06-22 | J7: 9340 | M7: 1966-03-08 | N7: 929
A8: 1967 | I8: 1967-06-22 | J8: 13500 | K8: 1967-06-22 09:45 | L8: 13700 | M8: 1967-03-16 | N8: 1020
A9: 1968 | I9: 1968-07-10 | J9: 10200 | M9: 1968-01-13 | N9: 1150
A10: 1969 | B10: 1969-06-10 | C10: 5.578 | D10: =C10+$H$3 -> 5.621 | E10: 1969-06-09 10:40 | F10: 5.602 | G10: 1969-03-24 | H10: 0.61 | I10: 1969-06-10 | J10: 9660 | K10: 1969-06-13 09:30 | L10: 9740 | M10: 1969-03-15 | N10: 917
A11: 1970 | B11: 1970-06-09 | C11: 5.523 | D11: =C11+$H$3 -> 5.566 | E11: 1970-06-09 10:48 | F11: 5.566 | G11: 1970-11-22 | H11: 0.546 | I11: 1970-06-09 | J11: 9570 | M11: 1970-12-01 | N11: 830
A12: 1971 | B12: 1971-06-11 | C12: 5.52 | D12: =C12+$H$3 -> 5.563 | E12: 1971-06-12 11:21 | F12: 5.56 | G12: 1971-01-03 | H12: 0.433 | I12: 1971-06-08 | J12: 9570 | M12: 1971-01-07 | N12: 799
A13: 1972 | B13: 1972-06-17 | C13: 7.077 | D13: =C13+$H$3 -> 7.12 | E13: 1972-06-17 12:00 | F13: 7.108 | G13: 1972-12-13 | H13: 0.622 | I13: 1972-06-17 | J13: 14400 | M13: 1972-12-10 | N13: 725 | O13: min flow E
A14: 1973 | B14: 1973-06-29 | C14: 5.224 | D14: =C14+$H$3 -> 5.267 | E14: 1973-06-29 07:36 | F14: 5.264 | G14: 1973-03-28 | H14: 0.512 | I14: 1973-06-29 | J14: 8980 | M14: 1973-02-16 | N14: 985
A15: 1974 | B15: 1974-06-21 | C15: 6.77 | D15: =C15+$H$3 -> 6.813 | G15: 1974-01-02 | H15: 0.57 | I15: 1974-06-21 | J15: 13100 | K15: 1974-06-21 08:24 | L15: 13400 | M15: 1974-01-07 | N15: 937
A16: 1975 | B16: 1975-07-12 | C16: 5.319 | D16: =C16+$H$3 -> 5.362 | G16: 1975-04-06 | H16: 0.454 | I16: 1975-07-12 | J16: 9150 | K16: 1975-07-12 00:19 | L16: 9230 | M16: 1975-01-17 | N16: 818
A17: 1976 | B17: 1976-06-23 | C17: 5.767 | D17: =C17+$H$3 -> 5.81 | E17: 1976-06-24 07:59 | F17: 5.785 | G17: 1976-03-06 | H17: 0.475 | I17: 1976-06-23 | J17: 10100 | K17: 1976-06-24 07:59 | L17: 10100 | M17: 1976-03-06 | N17: 1040
A18: 1977 | B18: 1977-06-26 | C18: 4.173 | D18: =C18+$H$3 -> 4.216 | G18: 1977-03-30 | H18: 0.521 | I18: 1977-06-26 | J18: 7110 | K18: 1977-06-26 03:21 | L18: 7160 | M18: 1977-11-25 | N18: 1030
A19: 1978 | B19: 1978-06-10 | C19: 4.532 | D19: =C19+$H$3 -> 4.575 | G19: 1978-03-16 | H19: 0.472 | I19: 1978-06-10 | J19: 7730 | K19: 1978-06-09 23:40 | L19: 7820 | M19: 1978-02-05 | N19: 915
A20: 1979 | B20: 1979-06-10 | C20: 4.932 | D20: =C20+$H$3 -> 4.975 | E20: 1979-06-10 09:39 | F20: 4.992 | I20: 1979-06-10 | J20: 8440 | K20: 1979-06-10 09:38 | L20: 8550 | M20: 1979-02-02 | N20: 838 | O20: min flow B
A21: 1980 | B21: 1980-12-27 | C21: 4.608 | D21: =C21+$H$3 -> 4.651 | E21: 1980-12-27 15:01 | F21: 4.825 | I21: 1980-12-27 | J21: 7850 | K21: 1980-12-27 15:01 | L21: 8230 | M21: 1980-02-15 | N21: 648
A22: 1981 | B22: 1981-05-31 | C22: 5.029 | D22: =C22+$H$3 -> 5.072 | E22: 1981-06-06 13:16 | F22: 5.081 | I22: 1981-05-31 | J22: 8610 | K22: 1981-06-06 13:16 | L22: 8700 | M22: 1981-12-31 | N22: 1330
A23: 1982 | B23: 1982-06-22 | C23: 6.168 | D23: =C23+$H$3 -> 6.211 | E23: 1982-06-22 09:06 | F23: 6.252 | I23: 1982-06-21 | J23: 11100 | K23: 1982-06-22 09:06 | L23: 11300 | M23: 1982-01-07 | N23: 858
A24: 1983 | B24: 1983-06-04 | C24: 4.664 | D24: =C24+$H$3 -> 4.707 | E24: 1983-06-04 06:01 | F24: 4.696 | G24: 1983-10-18 | H24: 0.611 | I24: 1983-06-04 | J24: 8490 | M24: 1983-01-01 | N24: 1160
A25: 1984 | B25: 1984-07-02 | C25: 5.234 | D25: =C25+$H$3 -> 5.277 | E25: 1984-07-02 16:00 | F25: 5.238 | G25: 1984-12-31 | H25: 0.445 | I25: 1984-07-03 | J25: 9120 | K25: 1984-07-02 16:00 | L25: 9270 | M25: 1984-12-31 | N25: 900 | O25: min flow B
A26: 1985 | B26: 1985-06-08 | C26: 5.622 | D26: =C26+$H$3 -> 5.665 | E26: 1985-06-08 12:32 | F26: 5.676 | G26: 1985-02-27 | H26: 0.362 | I26: 1985-05-29 | J26: 11000 | K26: 1985-05-28 20:15 | L26: 11100 | M26: 1985-12-01 | N26: 805 | O26: min flow B
A27: 1986 | B27: 1986-06-05 | C27: 6.137 | D27: =C27+$H$3 -> 6.18 | E27: 1986-06-06 07:49 | F27: 6.189 | G27: 1986-12-09 | H27: 0.507 | I27: 1986-06-04 | J27: 12400 | K27: 1986-06-04 12:45 | L27: 12600 | M27: 1986-01-05 | N27: 947
A28: 1987 | B28: 1987-06-17 | C28: 4.553 | D28: =C28+$H$3 -> 4.596 | E28: 1987-06-17 11:52 | F28: 4.603 | G28: 1987-12-26 | H28: 0.405 | I28: 1987-06-17 | J28: 8500 | K28: 1987-06-16 18:30 | L28: 8640 | M28: 1987-12-31 | N28: 979
A29: 1988 | B29: 1988-05-17 | C29: 4.668 | D29: =C29+$H$3 -> 4.711 | E29: 1988-05-18 09:08 | F29: 4.759 | G29: 1988-02-05 | H29: 0.353 | I29: 1988-05-18 | J29: 8050 | K29: 1988-05-18 12:00 | L29: 8240 | M29: 1988-01-09 | N29: 682 | O29: min level E; min flow E
A30: 1989 | B30: 1989-06-19 | C30: 4.556 | D30: =C30+$H$3 -> 4.599 | E30: 1989-06-19 07:06 | F30: 4.639 | G30: 1989-01-28 | H30: 0.446 | I30: 1989-06-09 | J30: 7980 | K30: 1989-06-09 19:00 | L30: 8150 | M30: 1989-03-03 | N30: 879 | O30: min flow E
A31: 1990 | G31: 1990-12-24 | H31: 0.511 | I31: 1990-06-16 | J31: 10800 | K31: 1990-06-17 03:05 | L31: 11100 | M31: 1990-12-30 | N31: 1030 | O31: min flow B
A32: 1991 | B32: 1991-07-04 | C32: 4.943 | D32: =C32+$H$3 -> 4.986 | E32: 1991-07-04 04:02 | F32: 4.971 | G32: 1991-11-01 | H32: 0.577 | I32: 1991-07-04 | J32: 8890 | K32: 1991-07-04 04:02 | L32: 9060 | M32: 1991-01-09 | N32: 920 | O32: min flow B
A33: 1992 | B33: 1992-06-18 | C33: 4.022 | D33: =C33+$H$3 -> 4.065 | E33: 1992-06-17 23:49 | F33: 4.099 | G33: 1992-12-31 | H33: 0.633 | I33: 1992-06-18 | J33: 7240 | K33: 1992-06-17 16:30 | L33: 7440 | M33: 1992-12-31 | N33: 820 | O33: min flow E
A34: 1993 | B34: No data published (gauge gap 1993–1996)
A35: 1994 | B35: No data published (gauge gap 1993–1996)
A36: 1995 | B36: No data published (gauge gap 1993–1996)
A37: 1996 | B37: No data published (gauge gap 1993–1996)
A38: 1997 | B38: 1997-06-05 | C38: 6.325 | D38: =C38+$H$3 -> 6.368 | E38: 1997-06-05 07:15 | F38: 6.394
A39: 1998 | B39: 1998-06-01 | C39: 4.078 | D39: =C39+$H$3 -> 4.121 | E39: 1998-06-01 02:00 | F39: 4.131
A40: 1999 | B40: 1999-06-23 | C40: 6.214 | D40: =C40+$H$3 -> 6.257 | E40: 1999-06-23 05:00 | F40: 6.257 | G40: 1999-03-11 | H40: 0.704
A41: 2000 | B41: 2000-06-15 | C41: 4.758 | D41: =C41+$H$3 -> 4.801 | E41: 2000-06-15 05:31 | F41: 4.862 | G41: 2000-12-18 | H41: 0.37 | I41: 2000-06-15 | J41: 8470 | K41: 2000-06-15 05:31 | L41: 8660
...

Sheet Harrison Lake 1933-2025
A1: Harrison Lake near Harrison Hot Springs (WSC 08MG012) — annual maximum and minimum lake level
A2: Source: Water Survey of Canada / ECCC Water Office (HYDAT), Annual Extremes & Peak reports, retrieved 2026-10-05. Level only (no discharge measured at this station). Published in GSC datum.
A3: GSC → CGVD2013 datum, add (m): | F3: 0.148
A5: Year | B5: Max daily level date | C5: Max daily level (m GSC) | D5: Max instantaneous level date/time (PST) | E5: Max instantaneous level (m GSC) | F5: Min daily level date | G5: Min daily level (m GSC) | H5: Min instantaneous level date/time (PST) | I5: Min instantaneous level (m GSC) | J5: Annual range, daily (m) | K5: Flags
A6: 1933 | B6: 1933-07-18 | C6: 11.826
A7: 1934 | B7: 1934-06-14 | C7: 11.47 | F7: 1934-10-06 | G7: 9.235 | J7: =C7-G7 -> 2.235
A8: 1935 | B8: 1935-06-13 | C8: 11.393 | F8: 1935-04-12 | G8: 9.135 | J8: =C8-G8 -> 2.258
A9: 1936 | B9: 1936-06-05 | C9: 12.308 | F9: 1936-02-19 | G9: 8.702 | J9: =C9-G9 -> 3.606
A10: 1937 | B10: 1937-06-12 | C10: 11.521 | F10: 1937-02-08 | G10: 8.626 | J10: =C10-G10 -> 2.895
A11: 1938 | B11: 1938-06-26 | C11: 11.521 | F11: 1938-02-19 | G11: 8.83 | J11: =C11-G11 -> 2.691
A12: 1939 | B12: 1939-12-10 | C12: 11.393 | F12: 1939-03-16 | G12: 8.726 | J12: =C12-G12 -> 2.667
A13: 1940 | B13: 1940-10-23 | C13: 11.268 | F13: 1940-01-26 | G13: 9.107 | J13: =C13-G13 -> 2.161
A14: 1941 | B14: 1941-12-04 | C14: 11.064 | F14: 1941-03-16 | G14: 9.107 | J14: =C14-G14 -> 1.957
A15: 1942 | B15: 1942-06-10 | C15: 11.268 | F15: 1942-02-28 | G15: 8.803 | J15: =C15-G15 -> 2.465
A16: 1943 | B16: 1943-07-05 | C16: 11.317 | F16: 1943-03-19 | G16: 8.906 | J16: =C16-G16 -> 2.411
A17: 1944 | B17: 1944-06-14 | C17: 10.811 | F17: 1944-03-07 | G17: 8.702 | J17: =C17-G17 -> 2.109
A18: 1945 | B18: 1945-06-02 | C18: 11.521 | F18: 1945-03-07 | G18: 9.031 | J18: =C18-G18 -> 2.49
... A24: 1951 | B24: 1951-07-04 | C24: 11.293 | F24: 1951-12-31 | G24: 8.778 | J24: =C24-G24 -> 2.515
A25: 1952 | B25: 1952-06-07 | C25: 11.305 | D25: 1952-06-07 12:30 | E25: 11.329 | F25: 1952-01-19 | G25: 8.428 | J25: =C25-G25 -> 2.877 | K25: min A
A26: 1953 | B26: 1953-07-16 | C26: 11.357 | D26: 1953-07-17 10:15 | E26: 11.363 | F26: 1953-03-10 | G26: 8.891 | J26: =C26-G26 -> 2.466
A27: 1954 | B27: 1954-07-11 | C27: 11.689 | D27: 1954-07-11 15:30 | E27: 11.704 | F27: 1954-02-03 | G27: 8.891 | J27: =C27-G27 -> 2.798
A28: 1955 | B28: 1955-07-18 | C28: 11.72 | D28: 1955-07-18 11:00 | E28: 11.735 | F28: 1955-03-28 | G28: 8.565 | J28: =C28-G28 -> 3.155
A29: 1956 | B29: 1956-06-11 | C29: 12.213 | D29: 1956-06-11 09:30 | E29: 12.241
A30: 1957 | B30: 1957-06-06 | C30: 11.445 | D30: 1957-06-06 10:50 | E30: 11.448
A31: 1958 | B31: 1958-05-30 | C31: 11.969 | D31: 1958-05-30 07:15 | E31: 11.994 | F31: 1958-04-08 | G31: 9.019 | J31: =C31-G31 -> 2.95
A32: 1959 | B32: 1959-06-26 | C32: 11.512 | D32: 1959-06-26 06:00 | E32: 11.515 | F32: 1959-02-25 | G32: 8.784 | J32: =C32-G32 -> 2.728
A33: 1960 | B33: 1960-07-08 | C33: 11.47 | D33: 1960-07-09 02:15 | E33: 11.482
A34: 1961 | B34: 1961-06-08 | C34: 12.085 | F34: 1961-12-20 | G34: 8.839 | J34: =C34-G34 -> 3.246
A35: 1962 | B35: 1962-06-27 | C35: 11.089 | F35: 1962-03-23 | G35: 8.544 | J35: =C35-G35 -> 2.545
A36: 1963 | B36: 1963-06-20 | C36: 11.14 | D36: 1963-06-20 14:00 | E36: 11.156 | F36: 1963-02-02 | G36: 8.772 | J36: =C36-G36 -> 2.368
A37: 1964 | B37: 1964-06-16 | C37: 12.244 | D37: 1964-06-16 13:45 | E37: 12.259
A38: 1965 | B38: 1965-06-12 | C38: 11.204 | D38: 1965-06-12 08:00 | E38: 11.217
A39: 1966 | B39: 1966-06-20 | C39: 11.192 | D39: 1966-06-20 20:20 | E39: 11.238 | F39: 1966-03-06 | G39: 8.675 | J39: =C39-G39 -> 2.517
A40: 1967 | B40: 1967-06-24 | C40: 12.823 | D40: 1967-06-24 17:15 | E40: 12.838 | F40: 1967-03-15 | G40: 8.793 | J40: =C40-G40 -> 4.03
A41: 1968 | B41: 1968-07-13 | C41: 11.933 | D41: 1968-07-11 12:30 | E41: 11.942
A42: 1969 | B42: 1969-06-14 | C42: 12.354 | D42: 1969-06-14 22:28 | E42: 12.366
A43: 1970 | B43: 1970-06-09 | C43: 11.305 | D43: 1970-06-10 02:55 | E43: 11.314 | F43: 1970-11-07 | G43: 8.708 | J43: =C43-G43 -> 2.597
A44: 1971 | B44: 1971-06-09 | C44: 11.457 | D44: 1971-06-09 08:57 | E44: 11.47 | F44: 1971-01-13 | G44: 8.556 | J44: =C44-G44 -> 2.901
A45: 1972 | B45: 1972-06-12 | C45: 12.5 | D45: 1972-06-12 08:24 | E45: 12.509 | F45: 1972-12-15 | G45: 8.55 | J45: =C45-G45 -> 3.95
A46: 1973 | B46: 1973-06-30 | C46: 11.052 | D46: 1973-06-30 15:30 | E46: 11.055 | F46: 1973-02-24 | G46: 8.675 | J46: =C46-G46 -> 2.377
...

Sheet Historic Peaks 1876-
A1: Largest recorded floods at Mission — full period of record (1876 onward)
A2: Pre-1969 water levels are NOT in the online HYDAT database; they come from published WSC values summarised in NHC (2008), Table 2.3.
A3: Harrison Lake (08MG012) levels are already in GSC datum, so they compare directly with Mission. Lake record begins July 1933.
A4: Rank (NHC 2008) | B4: Year | C4: Date | D4: Peak water level (m GSC) | E4: Max daily discharge at Mission (m³/s) | F4: Estimated peak at Hope (m³/s) | G4: Harrison Lake peak daily level (m GSC) | H4: Source / notes
A5: 1 | B5: 1894 | C5: Jun 05 | D5: 7.92 | F5: 17000 | G5: =IF(B5<1933,"before 1933 record",IFERROR(IF(INDEX('Harrison Lake 1933-2025'!$C$6:$C$98,MATCH(B5,'Harrison Lake 1933-2025'!$A$6:$A$98,0))="","not published",INDEX('Harrison Lake 1933-2025'!$C$6:$C$98,MATCH(B5,'Harrison Lake 1933-2025'!$A$6:$A$98,0))),"not published")) -> before 1933 record | H5: NHC 2008 Table 2.3. Flood of record. Hope flow estimated from 1934 high-water-mark survey.
A6: 2 | B6: 1948 | C6: May 31 | D6: 7.61 | F6: 15200 | G6: =IF(B6<1933,"before 1933 record",IFERROR(IF(INDEX('Harrison Lake 1933-2025'!$C$6:$C$98,MATCH(B6,'Harrison Lake 1933-2025'!$A$6:$A$98,0))="","not published",INDEX('Harrison Lake 1933-2025'!$C$6:$C$98,MATCH(B6,'Harrison Lake 1933-2025'!$A$6:$A$98,0))),"not published")) -> 13.298 | H6: NHC 2008 Table 2.3; Hope peak recorded 31 May 1948.
A7: 3 | B7: 1950 | C7: Jun 20 | D7: 7.45 | G7: =IF(B7<1933,"before 1933 record",IFERROR(IF(INDEX('Harrison Lake 1933-2025'!$C$6:$C$98,MATCH(B7,'Harrison Lake 1933-2025'!$A$6:$A$98,0))="","not published",INDEX('Harrison Lake 1933-2025'!$C$6:$C$98,MATCH(B7,'Harrison Lake 1933-2025'!$A$6:$A$98,0))),"not published")) -> 13.146 | H7: NHC 2008 Table 2.3
A8: 4 | B8: 1882 | C8: Jun 21 | D8: 7.34 | G8: =IF(B8<1933,"before 1933 record",IFERROR(IF(INDEX('Harrison Lake 1933-2025'!$C$6:$C$98,MATCH(B8,'Harrison Lake 1933-2025'!$A$6:$A$98,0))="","not published",INDEX('Harrison Lake 1933-2025'!$C$6:$C$98,MATCH(B8,'Harrison Lake 1933-2025'!$A$6:$A$98,0))),"not published")) -> before 1933 record | H8: NHC 2008 Table 2.3
A9: 5 | B9: 1972 | C9: Jun 17 | D9: ='Annual Extremes 1965-2025'!$H$3+INDEX('Annual Extremes 1965-2025'!F:F,MATCH(1972,'Annual Extremes 1965-2025'!A:A,0)) -> 7.151 | E9: 14400 | G9: =IF(B9<1933,"before 1933 record",IFERROR(IF(INDEX('Harrison Lake 1933-2025'!$C$6:$C$98,MATCH(B9,'Harrison Lake 1933-2025'!$A$6:$A$98,0))="","not published",INDEX('Harrison Lake 1933-2025'!$C$6:$C$98,MATCH(B9,'Harrison Lake 1933-2025'!$A$6:$A$98,0))),"not published")) -> 12.5 | H9: Level from Water Office (formula: assumed + offset). Uses instantaneous peak (7.108 m assumed) + offset = 7.15 m GSC, matching NHC.
A10: 6 | B10: 1964 | C10: Jun 05 | D10: 7.01 | G10: =IF(B10<1933,"before 1933 record",IFERROR(IF(INDEX('Harrison Lake 1933-2025'!$C$6:$C$98,MATCH(B10,'Harrison Lake 1933-2025'!$A$6:$A$98,0))="","not published",INDEX('Harrison Lake 1933-2025'!$C$6:$C$98,MATCH(B10,'Harrison Lake 1933-2025'!$A$6:$A$98,0))),"not published")) -> 12.244 | H10: NHC 2008 Table 2.3
A11: 7 | B11: 1876 | C11: Jun 22 | D11: 7 | G11: =IF(B11<1933,"before 1933 record",IFERROR(IF(INDEX('Harrison Lake 1933-2025'!$C$6:$C$98,MATCH(B11,'Harrison Lake 1933-2025'!$A$6:$A$98,0))="","not published",INDEX('Harrison Lake 1933-2025'!$C$6:$C$98,MATCH(B11,'Harrison Lake 1933-2025'!$A$6:$A$98,0))),"not published")) -> before 1933 record | H11: NHC 2008 Table 2.3 — first year of record
A12: 8 | B12: 1936 | C12: Jun 05 | D12: 6.97 | G12: =IF(B12<1933,"before 1933 record",IFERROR(IF(INDEX('Harrison Lake 1933-2025'!$C$6:$C$98,MATCH(B12,'Harrison Lake 1933-2025'!$A$6:$A$98,0))="","not published",INDEX('Harrison Lake 1933-2025'!$C$6:$C$98,MATCH(B12,'Harrison Lake 1933-2025'!$A$6:$A$98,0))),"not published")) -> 12.308 | H12: NHC 2008 Table 2.3
A13: 9 | B13: 1967 | C13: Jun 22 | D13: 6.97 | E13: 13500 | G13: =IF(B13<1933,"before 1933 record",IFERROR(IF(INDEX('Harrison Lake 1933-2025'!$C$6:$C$98,MATCH(B13,'Harrison Lake 1933-2025'!$A$6:$A$98,0))="","not published",INDEX('Harrison Lake 1933-2025'!$C$6:$C$98,MATCH(B13,'Harrison Lake 1933-2025'!$A$6:$A$98,0))),"not published")) -> 12.823 | H13: NHC 2008 Table 2.3; flow from Water Office
A14: 10 | B14: 1903 | C14: Jun 21 | D14: 6.93 | G14: =IF(B14<1933,"before 1933 record",IFERROR(IF(INDEX('Harrison Lake 1933-2025'!$C$6:$C$98,MATCH(B14,'Harrison Lake 1933-2025'!$A$6:$A$98,0))="","not published",INDEX('Harrison Lake 1933-2025'!$C$6:$C$98,MATCH(B14,'Harrison Lake 1933-2025'!$A$6:$A$98,0))),"not published")) -> before 1933 record | H14: NHC 2008 Table 2.3
A16: Recent comparison (Water Office, daily max converted to GSC):
B17: 2012 | D17: =INDEX('Annual Extremes 1965-2025'!D:D,MATCH(2012,'Annual Extremes 1965-2025'!A:A,0)) -> 6.369 | E17: =INDEX('Annual Extremes 1965-2025'!J:J,MATCH(2012,'Annual Extremes 1965-2025'!A:A,0)) -> 12700 | G17: =IF(B17<1933,"before 1933 record",IFERROR(IF(INDEX('Harrison Lake 1933-2025'!$C$6:$C$98,MATCH(B17,'Harrison Lake 1933-2025'!$A$6:$A$98,0))="","not published",INDEX('Harrison Lake 1933-2025'!$C$6:$C$98,MATCH(B17,'Harrison Lake 1933-2025'!$A$6:$A$98,0))),"not published")) -> 12.42
B18: 2018 | D18: =INDEX('Annual Extremes 1965-2025'!D:D,MATCH(2018,'Annual Extremes 1965-2025'!A:A,0)) -> 5.961 | E18: =INDEX('Annual Extremes 1965-2025'!J:J,MATCH(2018,'Annual Extremes 1965-2025'!A:A,0)) -> 11700 | G18: =IF(B18<1933,"before 1933 record",IFERROR(IF(INDEX('Harrison Lake 1933-2025'!$C$6:$C$98,MATCH(B18,'Harrison Lake 1933-2025'!$A$6:$A$98,0))="","not published",INDEX('Harrison Lake 1933-2025'!$C$6:$C$98,MATCH(B18,'Harrison Lake 1933-2025'!$A$6:$A$98,0))),"not published")) -> 12.312
B19: 2020 | D19: =INDEX('Annual Extremes 1965-2025'!D:D,MATCH(2020,'Annual Extremes 1965-2025'!A:A,0)) -> 5.867 | E19: =INDEX('Annual Extremes 1965-2025'!J:J,MATCH(2020,'Annual Extremes 1965-2025'!A:A,0)) -> 11400 | G19: =IF(B19<1933,"before 1933 record",IFERROR(IF(INDEX('Harrison Lake 1933-2025'!$C$6:$C$98,MATCH(B19,'Harrison Lake 1933-2025'!$A$6:$A$98,0))="","not published",INDEX('Harrison Lake 1933-2025'!$C$6:$C$98,MATCH(B19,'Harrison Lake 1933-2025'!$A$6:$A$98,0))),"not published")) -> not published
B20: 2021 | C20: Jun 07 | D20: =INDEX('Annual Extremes 1965-2025'!D:D,MATCH(2021,'Annual Extremes 1965-2025'!A:A,0)) -> 5.453 | E20: =INDEX('Annual Extremes 1965-2025'!J:J,MATCH(2021,'Annual Extremes 1965-2025'!A:A,0)) -> 10500 | G20: =IF(B20<1933,"before 1933 record",IFERROR(IF(INDEX('Harrison Lake 1933-2025'!$C$6:$C$98,MATCH(B20,'Harrison Lake 1933-2025'!$A$6:$A$98,0))="","not published",INDEX('Harrison Lake 1933-2025'!$C$6:$C$98,MATCH(B20,'Harrison Lake 1933-2025'!$A$6:$A$98,0))),"not published")) -> 12.235 | H20: 2021 June freshet: Mission peak Jun 7, Harrison Lake peak Jul 1 (annual daily maximums).
B21: 2022 | D21: =INDEX('Annual Extremes 1965-2025'!D:D,MATCH(2022,'Annual Extremes 1965-2025'!A:A,0)) -> 5.867 | E21: =INDEX('Annual Extremes 1965-2025'!J:J,MATCH(2022,'Annual Extremes 1965-2025'!A:A,0)) -> 11400 | G21: =IF(B21<1933,"before 1933 record",IFERROR(IF(INDEX('Harrison Lake 1933-2025'!$C$6:$C$98,MATCH(B21,'Harrison Lake 1933-2025'!$A$6:$A$98,0))="","not published",INDEX('Harrison Lake 1933-2025'!$C$6:$C$98,MATCH(B21,'Harrison Lake 1933-2025'!$A$6:$A$98,0))),"not published")) -> 12.075
B22: 2021 | C22: Nov 15 | D22: ='Annual Extremes 1965-2025'!$H$3+4.666 -> 4.709 | E22: 8970 | G22: 12.042 | H22: Nov 2021 atmospheric river. Mission daily level 4.666 m assumed (Nov 15) and daily flow 8,970 m³/s (Nov 15); instantaneous peak 5.539 m assumed (5.58 m GSC) and 10,800 m³/s at 22:20 PST Nov 15. Harrison Lake daily level 12.042 m GSC on Nov 16. Source: WSC daily tables, 2021.
A25: Ten highest Harrison Lake levels, 1933–2025 (WSC 08MG012, daily maximum)
A26: Rank | B26: Year | C26: Date | D26: Harrison Lake level (m GSC) | E26: Mission peak same year (m GSC) | H26: Notes
A27: 1 | B27: =INDEX('Harrison Lake 1933-2025'!$A$6:$A$98,MATCH(D27,'Harrison Lake 1933-2025'!$C$6:$C$98,0)) -> 1948 | C27: =INDEX('Harrison Lake 1933-2025'!$B$6:$B$98,MATCH(D27,'Harrison Lake 1933-2025'!$C$6:$C$98,0)) -> 1948-06-11 | D27: =LARGE('Harrison Lake 1933-2025'!$C$6:$C$98,A27) -> 13.298 | E27: =IFERROR(INDEX($D$5:$D$14,MATCH(B27,$B$5:$B$14,0)),IFERROR(INDEX('Annual Extremes 1965-2025'!$D$6:$D$66,MATCH(B27,'Annual Extremes 1965-2025'!$A$6:$A$66,0)),"-")) -> 7.61
A28: 2 | B28: =INDEX('Harrison Lake 1933-2025'!$A$6:$A$98,MATCH(D28,'Harrison Lake 1933-2025'!$C$6:$C$98,0)) -> 1950 | C28: =INDEX('Harrison Lake 1933-2025'!$B$6:$B$98,MATCH(D28,'Harrison Lake 1933-2025'!$C$6:$C$98,0)) -> 1950-06-22 | D28: =LARGE('Harrison Lake 1933-2025'!$C$6:$C$98,A28) -> 13.146 | E28: =IFERROR(INDEX($D$5:$D$14,MATCH(B28,$B$5:$B$14,0)),IFERROR(INDEX('Annual Extremes 1965-2025'!$D$6:$D$66,MATCH(B28,'Annual Extremes 1965-2025'!$A$6:$A$66,0)),"-")) -> 7.45
A29: 3 | B29: =INDEX('Harrison Lake 1933-2025'!$A$6:$A$98,MATCH(D29,'Harrison Lake 1933-2025'!$C$6:$C$98,0)) -> 1967 | C29: =INDEX('Harrison Lake 1933-2025'!$B$6:$B$98,MATCH(D29,'Harrison Lake 1933-2025'!$C$6:$C$98,0)) -> 1967-06-24 | D29: =LARGE('Harrison Lake 1933-2025'!$C$6:$C$98,A29) -> 12.823 | E29: =IFERROR(INDEX($D$5:$D$14,MATCH(B29,$B$5:$B$14,0)),IFERROR(INDEX('Annual Extremes 1965-2025'!$D$6:$D$66,MATCH(B29,'Annual Extremes 1965-2025'!$A$6:$A$66,0)),"-")) -> 6.97
A30: 4 | B30: =INDEX('Harrison Lake 1933-2025'!$A$6:$A$98,MATCH(D30,'Harrison Lake 1933-2025'!$C$6:$C$98,0)) -> 1974 | C30: =INDEX('Harrison Lake 1933-2025'!$B$6:$B$98,MATCH(D30,'Harrison Lake 1933-2025'!$C$6:$C$98,0)) -> 1974-06-23 | D30: =LARGE('Harrison Lake 1933-2025'!$C$6:$C$98,A30) -> 12.619 | E30: =IFERROR(INDEX($D$5:$D$14,MATCH(B30,$B$5:$B$14,0)),IFERROR(INDEX('Annual Extremes 1965-2025'!$D$6:$D$66,MATCH(B30,'Annual Extremes 1965-2025'!$A$6:$A$66,0)),"-")) -> 6.813
A31: 5 | B31: =INDEX('Harrison Lake 1933-2025'!$A$6:$A$98,MATCH(D31,'Harrison Lake 1933-2025'!$C$6:$C$98,0)) -> 1972 | C31: =INDEX('Harrison Lake 1933-2025'!$B$6:$B$98,MATCH(D31,'Harrison Lake 1933-2025'!$C$6:$C$98,0)) -> 1972-06-12 | D31: =LARGE('Harrison Lake 1933-2025'!$C$6:$C$98,A31) -> 12.5 | E31: =IFERROR(INDEX($D$5:$D$14,MATCH(B31,$B$5:$B$14,0)),IFERROR(INDEX('Annual Extremes 1965-2025'!$D$6:$D$66,MATCH(B31,'Annual Extremes 1965-2025'!$A$6:$A$66,0)),"-")) -> 7.151
A32: 6 | B32: =INDEX('Harrison Lake 1933-2025'!$A$6:$A$98,MATCH(D32,'Harrison Lake 1933-2025'!$C$6:$C$98,0)) -> 1982 | C32: =INDEX('Harrison Lake 1933-2025'!$B$6:$B$98,MATCH(D32,'Harrison Lake 1933-2025'!$C$6:$C$98,0)) -> 1982-06-23 | D32: =LARGE('Harrison Lake 1933-2025'!$C$6:$C$98,A32) -> 12.423 | E32: =IFERROR(INDEX($D$5:$D$14,MATCH(B32,$B$5:$B$14,0)),IFERROR(INDEX('Annual Extremes 1965-2025'!$D$6:$D$66,MATCH(B32,'Annual Extremes 1965-2025'!$A$6:$A$66,0)),"-")) -> 6.211
A33: 7 | B33: =INDEX('Harrison Lake 1933-2025'!$A$6:$A$98,MATCH(D33,'Harrison Lake 1933-2025'!$C$6:$C$98,0)) -> 2012 | C33: =INDEX('Harrison Lake 1933-2025'!$B$6:$B$98,MATCH(D33,'Harrison Lake 1933-2025'!$C$6:$C$98,0)) -> 2012-06-25 | D33: =LARGE('Harrison Lake 1933-2025'!$C$6:$C$98,A33) -> 12.42 | E33: =IFERROR(INDEX($D$5:$D$14,MATCH(B33,$B$5:$B$14,0)),IFERROR(INDEX('Annual Extremes 1965-2025'!$D$6:$D$66,MATCH(B33,'Annual Extremes 1965-2025'!$A$6:$A$66,0)),"-")) -> 6.369
A34: 8 | B34: =INDEX('Harrison Lake 1933-2025'!$A$6:$A$98,MATCH(D34,'Harrison Lake 1933-2025'!$C$6:$C$98,0)) -> 1969 | C34: =INDEX('Harrison Lake 1933-2025'!$B$6:$B$98,MATCH(D34,'Harrison Lake 1933-2025'!$C$6:$C$98,0)) -> 1969-06-14 | D34: =LARGE('Harrison Lake 1933-2025'!$C$6:$C$98,A34) -> 12.354 | E34: =IFERROR(INDEX($D$5:$D$14,MATCH(B34,$B$5:$B$14,0)),IFERROR(INDEX('Annual Extremes 1965-2025'!$D$6:$D$66,MATCH(B34,'Annual Extremes 1965-2025'!$A$6:$A$66,0)),"-")) -> 5.621
A35: 9 | B35: =INDEX('Harrison Lake 1933-2025'!$A$6:$A$98,MATCH(D35,'Harrison Lake 1933-2025'!$C$6:$C$98,0)) -> 2018 | C35: =INDEX('Harrison Lake 1933-2025'!$B$6:$B$98,MATCH(D35,'Harrison Lake 1933-2025'!$C$6:$C$98,0)) -> 2018-05-21 | D35: =LARGE('Harrison Lake 1933-2025'!$C$6:$C$98,A35) -> 12.312 | E35: =IFERROR(INDEX($D$5:$D$14,MATCH(B35,$B$5:$B$14,0)),IFERROR(INDEX('Annual Extremes 1965-2025'!$D$6:$D$66,MATCH(B35,'Annual Extremes 1965-2025'!$A$6:$A$66,0)),"-")) -> 5.961
A36: 10 | B36: =INDEX('Harrison Lake 1933-2025'!$A$6:$A$98,MATCH(D36,'Harrison Lake 1933-2025'!$C$6:$C$98,0)) -> 1999 | C36: =INDEX('Harrison Lake 1933-2025'!$B$6:$B$98,MATCH(D36,'Harrison Lake 1933-2025'!$C$6:$C$98,0)) -> 1999-07-17 | D36: =LARGE('Harrison Lake 1933-2025'!$C$6:$C$98,A36) -> 12.31 | E36: =IFERROR(INDEX($D$5:$D$14,MATCH(B36,$B$5:$B$14,0)),IFERROR(INDEX('Annual Extremes 1965-2025'!$D$6:$D$66,MATCH(B36,'Annual Extremes 1965-2025'!$A$6:$A$66,0)),"-")) -> 6.257
A37: — | B37: 2021 | C37: 2021-11-16 | D37: 12.042 | E37: ='Annual Extremes 1965-2025'!$H$3+4.666 -> 4.709 | H37: Nov 2021 atmospheric river (not a top-ten level; shown for comparison). Harrison Lake daily level Nov 16; Mission daily level Nov 15 (peak hourly 5.58 m GSC). Source: WSC daily tables, 2021.
A38: Mission column uses the NHC top-ten value where the year is listed above, otherwise the Water Office daily maximum (converted to GSC); "-" = no Mission level published (1969 onward only).

Sheet Sources & Notes
A1: Item | B1: Detail
A2: Station | B2: FRASER RIVER AT MISSION, WSC station 08MH024, British Columbia
A3: Primary source | B3: ECCC Water Office historical reports (HYDAT): Annual Extremes (daily) and Peak (instantaneous) for Level and Flow — https://wateroffice.ec.gc.ca/report/historical_e.html?stn=08MH024
A4: Data availability | B4: https://wateroffice.ec.gc.ca/report/data_availability_e.html?type=historical&station=08MH024 — digital daily flow 1965–1992 continuous, 2000+ seasonal; daily level 1969–1992 and 1997+.
A5: Datum | B5: https://wateroffice.ec.gc.ca/report/datum_e.html?stn=08MH024 — published in assumed datum; +0.043 m to GSC; +0.137 m to CGVD2013.
A6: Data collection history | B6: 1876–1899 level, seasonal, manual · 1900–1935 level, seasonal, manual · 1936–1964 level, continuous recorder · 1965–1996 flow · 1997–98 flow & level · 1999 level · 2000–2026 flow & level.
A7: Why the drop-down starts in 1965 | B7: The 1876–1968 level readings were never loaded into HYDAT for this station; only the discharge record (from 1965) and level record (from 1969) are online. Pre-1965 discharge was never measured at Mission.
A8: Historic peaks source | B8: Northwest Hydraulic Consultants (M. Mannerström), "Comprehensive Review of Fraser River at Hope — Flood Hydrology and Flows", for BC Ministry of Environment, Oct 2008, Table 2.3 — https://www.env.gov.bc.ca/wsd/public_safety/flood/pdfs_word/review_fraser_flood_flows_hope.pdf
A9: Getting 1876–1968 annual values | B9: Request the archived Mission gauge annual maxima from Water Survey of Canada (BC/Yukon office) or BC River Forecast Centre; also printed WSC "Surface Water Data, British Columbia" and "Historical Streamflow Summary" volumes (library holdings).
A10: Licence | B10: Open Government Licence – Canada; credit Environment and Climate Change Canada.
A12: Station 2 | B12: HARRISON LAKE NEAR HARRISON HOT SPRINGS, WSC station 08MG012 — https://wateroffice.ec.gc.ca/report/historical_e.html?stn=08MG012
A13: 08MG012 record | B13: Lake level only, continuous since July 1933 (manual readings 1933–1951, recorder 1952 on). No discharge is measured at this station. The full record is in HYDAT, so the online table is complete back to the first year.
... A15: 08MG012 gaps | B15: No annual maximum published for 1981, 2019 and 2020; minimums missing in several years (incomplete winter record).
